Workbook

Sheet Dashboard
A1: Modern Bridal Veil Brand — Launch Model (3 Scenarios)
A2: Conservative / Base / Upside. Same SKU economics & startup costs; differ on traffic ramp, conversion and marketing.
A4: Metric | C4: Conservative | D4: Base | E4: Upside (Calily-match)
A5: 12-month gross revenue | C5: =Conservative!$B$53 -> 100605.96 | D5: =Base!$B$53 -> 221799.24 | E5: ='Upside (Calily-match)'!$B$53 -> 324153.18
A6: 12-month orders / units | C6: =Conservative!$B$54 -> 518 | D6: =Base!$B$54 -> 1142 | E6: ='Upside (Calily-match)'!$B$54 -> 1669
A7: 12-month operating profit | C7: =Conservative!$B$55 -> 22447.202 | D7: =Base!$B$55 -> 101455.69 | E7: ='Upside (Calily-match)'!$B$55 -> 155539.79
A8: Full-year operating margin | C8: =Conservative!$B$56 -> 0.22312001 | D8: =Base!$B$56 -> 0.45742125 | E8: ='Upside (Calily-match)'!$B$56 -> 0.47983422
A9: Lowest ending cash (the trough) | C9: =Conservative!$B$57 -> -1142.996 | D9: =Base!$B$57 -> 251.0688 | E9: ='Upside (Calily-match)'!$B$57 -> 581.6032
A10: Month of lowest cash | C10: =Conservative!$B$58 -> M4 | D10: =Base!$B$58 -> M2 | E10: ='Upside (Calily-match)'!$B$58 -> M2
A11: Ending cash (M12) | C11: =Conservative!$B$59 -> 24162.002 | D11: =Base!$B$59 -> 98070.886 | E11: ='Upside (Calily-match)'!$B$59 -> 148685.59
A12: Starting capital | C12: =Conservative!$B$60 -> 8000 | D12: =Base!$B$60 -> 8000 | E12: ='Upside (Calily-match)'!$B$60 -> 8000
A13: Capital verdict | C13: =IF(MIN(Conservative!B50:M50)>0,"Survives on $"&TEXT(Assumptions!$B$3,"#,##0"),"NEEDS MORE") -> NEEDS MORE | D13: =IF(MIN(Base!B50:M50)>0,"Survives on $"&TEXT(Assumptions!$B$3,"#,##0"),"NEEDS MORE") -> Survives on $8,000 | E13: =IF(MIN('Upside (Calily-match)'!B50:M50)>0,"Survives on $"&TEXT(Assumptions!$B$3,"#,##0"),"NEEDS MORE") -> Survives on $8,000
A15: KEY TAKEAWAYS
A16: • Calily's 17,276/month is total visits, not SEO visits. Its SEO share was 53.84%, or roughly 9.3k organic-search visits/month.
A17: • The new Channel Mix sheet separates SEO, organic social, creator/affiliate, direct/referral and paid traffic so the growth path is visible.
A18: • Base ends below Calily; Upside matches Calily on total sessions by M12. That makes the ceiling competitor-validated without overstating SEO.
A19: • Conversion still ramps from low new-site trust toward stronger product-page/review/UGC performance; it is not a flat 1.6% assumption.
A20: • Paid remains a small testing layer. The real engine is SEO pages + creator proof + Pinterest/TikTok discovery + direct/referral return visits.
A21: • Edit blue cells in Channel Mix, scenario tabs, SKU Economics and Assumptions. Green cells are linked formulas.

Sheet Conservative
A1: Monthly Operating Model — Conservative Case
A2: Lean new-domain case: SEO is slow, social/creator/direct carry early demand, and M12 remains well below Calily.
A3: Metric | B3: M1 | C3: M2 | D3: M3 | E3: M4 | F3: M5 | G3: M6 | H3: M7 | I3: M8 | J3: M9 | K3: M10 | L3: M11 | M3: M12 | N3: Note
A4: TRAFFIC
A5: Non-paid sessions subtotal | B5: ='Channel Mix'!B8 -> 400 | C5: ='Channel Mix'!C8 -> 540 | D5: ='Channel Mix'!D8 -> 750 | E5: ='Channel Mix'!E8 -> 1030 | F5: ='Channel Mix'!F8 -> 1470 | G5: ='Channel Mix'!G8 -> 2040 | H5: ='Channel Mix'!H8 -> 2740 | I5: ='Channel Mix'!I8 -> 3520 | ... M5: ='Channel Mix'!M8 -> 7100 | N5: From Channel Mix: SEO + organic social + creator/affiliate + direct/referral
A6: Paid ads budget ($) | B6: ='Channel Mix'!B9 -> 200 | C6: ='Channel Mix'!C9 -> 200 | D6: ='Channel Mix'!D9 -> 300 | E6: ='Channel Mix'!E9 -> 300 | F6: ='Channel Mix'!F9 -> 400 | G6: ='Channel Mix'!G9 -> 400 | H6: ='Channel Mix'!H9 -> 500 | I6: ='Channel Mix'!I9 -> 500 | ... M6: ='Channel Mix'!M9 -> 700 | N6: Small paid test layer; budget lives in Channel Mix
A7: CPC ($) | B7: =Assumptions!$B$8 -> 1.5 | C7: =Assumptions!$B$8 -> 1.5 | D7: =Assumptions!$B$8 -> 1.5 | E7: =Assumptions!$B$8 -> 1.5 | F7: =Assumptions!$B$8 -> 1.5 | G7: =Assumptions!$B$8 -> 1.5 | H7: =Assumptions!$B$8 -> 1.5 | I7: =Assumptions!$B$8 -> 1.5 | ... M7: =Assumptions!$B$8 -> 1.5 | N7: From Assumptions
A8: Paid sessions | B8: =ROUND(B6/B7,0) -> 133 | C8: =ROUND(C6/C7,0) -> 133 | D8: =ROUND(D6/D7,0) -> 200 | E8: =ROUND(E6/E7,0) -> 200 | F8: =ROUND(F6/F7,0) -> 267 | G8: =ROUND(G6/G7,0) -> 267 | H8: =ROUND(H6/H7,0) -> 333 | I8: =ROUND(I6/I7,0) -> 333 | ... M8: =ROUND(M6/M7,0) -> 467 | N8: Paid budget / CPC
A9: Total sessions | B9: =B5+B8 -> 533 | C9: =C5+C8 -> 673 | D9: =D5+D8 -> 950 | E9: =E5+E8 -> 1230 | F9: =F5+F8 -> 1737 | G9: =G5+G8 -> 2307 | H9: =H5+H8 -> 3073 | I9: =I5+I8 -> 3853 | ... M9: =M5+M8 -> 7567 | N9: Non-paid subtotal + paid sessions
A10: Conversion rate | B10: 0.007 | C10: 0.008 | D10: 0.009 | E10: 0.01 | F10: 0.011 | G10: 0.012 | H10: 0.0125 | I10: 0.013 | J10: 0.0135 | K10: 0.014 | L10: 0.0145 | M10: 0.015 | N10: Ramps up as reviews, UGC, product-page education and trust improve
A11: Orders / units sold | B11: =ROUND(B9*B10,0) -> 4 | C11: =ROUND(C9*C10,0) -> 5 | D11: =ROUND(D9*D10,0) -> 9 | E11: =ROUND(E9*E10,0) -> 12 | F11: =ROUND(F9*F10,0) -> 19 | G11: =ROUND(G9*G10,0) -> 28 | H11: =ROUND(H9*H10,0) -> 38 | I11: =ROUND(I9*I10,0) -> 50 | ... M11: =ROUND(M9*M10,0) -> 114 | N11: Total sessions x conversion
A12: REVENUE & GROSS PROFIT
A13: Weighted AOV | B13: ='SKU Economics'!$H$11 -> 194.22 | C13: ='SKU Economics'!$H$11 -> 194.22 | D13: ='SKU Economics'!$H$11 -> 194.22 | E13: ='SKU Economics'!$H$11 -> 194.22 | F13: ='SKU Economics'!$H$11 -> 194.22 | G13: ='SKU Economics'!$H$11 -> 194.22 | H13: ='SKU Economics'!$H$11 -> 194.22 | I13: ='SKU Economics'!$H$11 -> 194.22 | ... M13: ='SKU Economics'!$H$11 -> 194.22 | N13: Weighted realized price
A14: Gross revenue | B14: =B11*B13 -> 776.88 | C14: =C11*C13 -> 971.1 | D14: =D11*D13 -> 1747.98 | E14: =E11*E13 -> 2330.64 | F14: =F11*F13 -> 3690.18 | G14: =G11*G13 -> 5438.16 | H14: =H11*H13 -> 7380.36 | I14: =I11*I13 -> 9711 | ... M14: =M11*M13 -> 22141.08 | N14: Orders x AOV
A15: COGS | B15: =B11*'SKU Economics'!$F$11 -> 167.2 | C15: =C11*'SKU Economics'!$F$11 -> 209 | D15: =D11*'SKU Economics'!$F$11 -> 376.2 | E15: =E11*'SKU Economics'!$F$11 -> 501.6 | F15: =F11*'SKU Economics'!$F$11 -> 794.2 | G15: =G11*'SKU Economics'!$F$11 -> 1170.4 | H15: =H11*'SKU Economics'!$F$11 -> 1588.4 | I15: =I11*'SKU Economics'!$F$11 -> 2090 | ... M15: =M11*'SKU Economics'!$F$11 -> 4765.2 | N15: Units x weighted unit cost
A16: Payment / platform fee | B16: =B14*Assumptions!$B$4 -> 23.3064 | C16: =C14*Assumptions!$B$4 -> 29.133 | D16: =D14*Assumptions!$B$4 -> 52.4394 | E16: =E14*Assumptions!$B$4 -> 69.9192 | F16: =F14*Assumptions!$B$4 -> 110.7054 | G16: =G14*Assumptions!$B$4 -> 163.1448 | H16: =H14*Assumptions!$B$4 -> 221.4108 | I16: =I14*Assumptions!$B$4 -> 291.33 | ... M16: =M14*Assumptions!$B$4 -> 664.2324 | N16: % of revenue
A17: Return / loss reserve | B17: =B14*Assumptions!$B$5 -> 23.3064 | C17: =C14*Assumptions!$B$5 -> 29.133 | D17: =D14*Assumptions!$B$5 -> 52.4394 | E17: =E14*Assumptions!$B$5 -> 69.9192 | F17: =F14*Assumptions!$B$5 -> 110.7054 | G17: =G14*Assumptions!$B$5 -> 163.1448 | H17: =H14*Assumptions!$B$5 -> 221.4108 | I17: =I14*Assumptions!$B$5 -> 291.33 | ... M17: =M14*Assumptions!$B$5 -> 664.2324 | N17: % of revenue
A18: Variable gross profit | B18: =B14-B15-B16-B17 -> 563.0672 | C18: =C14-C15-C16-C17 -> 703.834 | D18: =D14-D15-D16-D17 -> 1266.9012 | E18: =E14-E15-E16-E17 -> 1689.2016 | F18: =F14-F15-F16-F17 -> 2674.5692 | G18: =G14-G15-G16-G17 -> 3941.4704 | H18: =H14-H15-H16-H17 -> 5349.1384 | I18: =I14-I15-I16-I17 -> 7038.34 | ... M18: =M14-M15-M16-M17 -> 16047.415 | N18: Rev - COGS - fee - reserve
A19: Variable gross margin | B19: =IFERROR(B18/B14,0) -> 0.72478015 | C19: =IFERROR(C18/C14,0) -> 0.72478015 | D19: =IFERROR(D18/D14,0) -> 0.72478015 | E19: =IFERROR(E18/E14,0) -> 0.72478015 | F19: =IFERROR(F18/F14,0) -> 0.72478015 | G19: =IFERROR(G18/G14,0) -> 0.72478015 | H19: =IFERROR(H18/H14,0) -> 0.72478015 | I19: =IFERROR(I18/I14,0) -> 0.72478015 | ... M19: =IFERROR(M18/M14,0) -> 0.72478015 | N19: VGP / revenue
A20: MARKETING (funds the traffic engine)
A21: Content & SEO investment | B21: 800 | C21: 800 | D21: 800 | E21: 800 | F21: 800 | G21: 800 | H21: 700 | I21: 700 | J21: 700 | K21: 700 | L21: 700 | M21: 700 | N21: Funds the organic ramp above; cutting this kills the organic engine
A22: Creator / UGC seeding | B22: 300 | C22: 300 | D22: 300 | E22: 300 | F22: 300 | G22: 300 | H22: 300 | I22: 300 | J22: 300 | K22: 300 | L22: 300 | M22: 300 | N22: Sample seeding, creator content
A23: Paid ads spend | B23: =B6 -> 200 | C23: =C6 -> 200 | D23: =D6 -> 300 | E23: =E6 -> 300 | F23: =F6 -> 400 | G23: =G6 -> 400 | H23: =H6 -> 500 | I23: =I6 -> 500 | ... M23: =M6 -> 700 | N23: Equals the paid budget above
A24: Total marketing | B24: =B21+B22+B23 -> 1300 | C24: =C21+C22+C23 -> 1300 | D24: =D21+D22+D23 -> 1400 | E24: =E21+E22+E23 -> 1400 | F24: =F21+F22+F23 -> 1500 | G24: =G21+G22+G23 -> 1500 | H24: =H21+H22+H23 -> 1500 | I24: =I21+I22+I23 -> 1500 | ... M24: =M21+M22+M23 -> 1700 | N24: Content + UGC + paid
A25: OPERATING EXPENSES (excl. marketing)
A26: Labor / founder / support | B26: 0 | C26: 0 | D26: 0 | E26: 0 | F26: 0 | G26: 1400 | H26: 1600 | I26: 1800 | J26: 2000 | K26: 2200 | L26: 2400 | M26: 2600 | N26: Founder takes nothing first 5 months
A27: Fulfillment / ops overhead | B27: 100 | C27: 120 | D27: 140 | E27: 160 | F27: 200 | G27: 250 | H27: 300 | I27: 360 | J27: 420 | K27: 480 | L27: 540 | M27: 600 | N27: Storage, pick-pack, QA, supplies
A28: Software / apps | B28: 250 | C28: 250 | D28: 300 | E28: 350 | F28: 400 | G28: 450 | H28: 500 | I28: 550 | J28: 600 | K28: 650 | L28: 700 | M28: 750 | N28: Shopify, email/SMS, reviews, analytics
A29: Admin / professional | B29: 200 | C29: 200 | D29: 250 | E29: 250 | F29: 300 | G29: 300 | H29: 350 | I29: 350 | J29: 400 | K29: 400 | L29: 450 | M29: 450 | N29: Accounting, legal, bookkeeping
A30: Contingency buffer | B30: 200 | C30: 200 | D30: 250 | E30: 300 | F30: 350 | G30: 400 | H30: 450 | I30: 500 | J30: 550 | K30: 600 | L30: 650 | M30: 700 | N30: Mistakes, rush fees, replacements
A31: Total opex excl. marketing | B31: =SUM(B26:B30) -> 750 | C31: =SUM(C26:C30) -> 770 | D31: =SUM(D26:D30) -> 940 | E31: =SUM(E26:E30) -> 1060 | F31: =SUM(F26:F30) -> 1250 | G31: =SUM(G26:G30) -> 2800 | H31: =SUM(H26:H30) -> 3200 | I31: =SUM(I26:I30) -> 3560 | ... M31: =SUM(M26:M30) -> 5100 | N31: Sum of operating lines
A32: PROFIT
A33: Operating profit before tax | B33: =B18-B24-B31 -> -1486.9328 | C33: =C18-C24-C31 -> -1366.166 | D33: =D18-D24-D31 -> -1073.0988 | E33: =E18-E24-E31 -> -770.7984 | F33: =F18-F24-F31 -> -75.4308 | G33: =G18-G24-G31 -> -358.5296 | H33: =H18-H24-H31 -> 649.1384 | I33: =I18-I24-I31 -> 1978.34 | ... M33: =M18-M24-M31 -> 9247.4152 | N33: VGP - marketing - opex
A34: Operating margin | B34: =IFERROR(B33/B14,0) -> -1.91398 | C34: =IFERROR(C33/C14,0) -> -1.4068232 | D34: =IFERROR(D33/D14,0) -> -0.61390794 | E34: =IFERROR(E33/E14,0) -> -0.33072392 | F34: =IFERROR(F33/F14,0) -> -0.020440954 | G34: =IFERROR(G33/G14,0) -> -0.065928476 | H34: =IFERROR(H33/H14,0) -> 0.087954842 | I34: =IFERROR(I33/I14,0) -> 0.20372155 | ... M34: =IFERROR(M33/M14,0) -> 0.41765872 | N34: Operating profit / revenue
A35: ACQUISITION EFFICIENCY
A36: Paid CAC ($/order) | B36: =IFERROR(B23/ROUND(B8*B10,0),0) -> 200 | C36: =IFERROR(C23/ROUND(C8*C10,0),0) -> 200 | D36: =IFERROR(D23/ROUND(D8*D10,0),0) -> 150 | E36: =IFERROR(E23/ROUND(E8*E10,0),0) -> 150 | F36: =IFERROR(F23/ROUND(F8*F10,0),0) -> 133.33333 | G36: =IFERROR(G23/ROUND(G8*G10,0),0) -> 133.33333 | H36: =IFERROR(H23/ROUND(H8*H10,0),0) -> 125 | I36: =IFERROR(I23/ROUND(I8*I10,0),0) -> 125 | ... M36: =IFERROR(M23/ROUND(M8*M10,0),0) -> 100 | N36: Paid spend / paid orders (now meaningful)
A37: Blended CAC ($/order) | B37: =IFERROR(B24/B11,0) -> 325 | C37: =IFERROR(C24/C11,0) -> 260 | D37: =IFERROR(D24/D11,0) -> 155.55556 | E37: =IFERROR(E24/E11,0) -> 116.66667 | F37: =IFERROR(F24/F11,0) -> 78.947368 | G37: =IFERROR(G24/G11,0) -> 53.571429 | H37: =IFERROR(H24/H11,0) -> 39.473684 | I37: =IFERROR(I24/I11,0) -> 30 | ... M37: =IFERROR(M24/M11,0) -> 14.912281 | N37: Total marketing / all orders
A38: MER (revenue / marketing) | B38: =IFERROR(B14/B24,0) -> 0.5976 | C38: =IFERROR(C14/C24,0) -> 0.747 | D38: =IFERROR(D14/D24,0) -> 1.2485571 | E38: =IFERROR(E14/E24,0) -> 1.6647429 | F38: =IFERROR(F14/F24,0) -> 2.46012 | G38: =IFERROR(G14/G24,0) -> 3.62544 | H38: =IFERROR(H14/H24,0) -> 4.92024 | I38: =IFERROR(I14/I24,0) -> 6.474 | ... M38: =IFERROR(M14/M24,0) -> 13.024165 | N38: Marketing efficiency ratio
A39: INVENTORY
A40: Opening inventory units | B40: =Assumptions!$B$7 -> 100 | C40: =B42 -> 96 | D40: =C42 -> 91 | E40: =D42 -> 82 | F40: =E42 -> 70 | G40: =F42 -> 51 | H40: =G42 -> 28 | I40: =H42 -> 38 | J40: =I42 -> 50 | ... M40: =L42 -> 96 | N40: M1 = initial units; else prior ending
...

Sheet Base
A1: Monthly Operating Model — Base Case
A2: Realistic SEO-led case: non-paid traffic compounds, but M12 total sessions remain below Calily's current benchmark.
A3: Metric | B3: M1 | C3: M2 | D3: M3 | E3: M4 | F3: M5 | G3: M6 | H3: M7 | I3: M8 | J3: M9 | K3: M10 | L3: M11 | M3: M12 | N3: Note
A4: TRAFFIC
A5: Non-paid sessions subtotal | B5: ='Channel Mix'!B20 -> 530 | C5: ='Channel Mix'!C20 -> 820 | D5: ='Channel Mix'!D20 -> 1270 | E5: ='Channel Mix'!E20 -> 1890 | F5: ='Channel Mix'!F20 -> 2800 | G5: ='Channel Mix'!G20 -> 3950 | H5: ='Channel Mix'!H20 -> 5350 | I5: ='Channel Mix'!I20 -> 6850 | ... M5: ='Channel Mix'!M20 -> 12600 | N5: From Channel Mix: SEO + organic social + creator/affiliate + direct/referral
A6: Paid ads budget ($) | B6: ='Channel Mix'!B21 -> 300 | C6: ='Channel Mix'!C21 -> 300 | D6: ='Channel Mix'!D21 -> 500 | E6: ='Channel Mix'!E21 -> 500 | F6: ='Channel Mix'!F21 -> 700 | G6: ='Channel Mix'!G21 -> 700 | H6: ='Channel Mix'!H21 -> 900 | I6: ='Channel Mix'!I21 -> 900 | ... M6: ='Channel Mix'!M21 -> 1300 | N6: Small paid test layer; budget lives in Channel Mix
A7: CPC ($) | B7: =Assumptions!$B$8 -> 1.5 | C7: =Assumptions!$B$8 -> 1.5 | D7: =Assumptions!$B$8 -> 1.5 | E7: =Assumptions!$B$8 -> 1.5 | F7: =Assumptions!$B$8 -> 1.5 | G7: =Assumptions!$B$8 -> 1.5 | H7: =Assumptions!$B$8 -> 1.5 | I7: =Assumptions!$B$8 -> 1.5 | ... M7: =Assumptions!$B$8 -> 1.5 | N7: From Assumptions
A8: Paid sessions | B8: =ROUND(B6/B7,0) -> 200 | C8: =ROUND(C6/C7,0) -> 200 | D8: =ROUND(D6/D7,0) -> 333 | E8: =ROUND(E6/E7,0) -> 333 | F8: =ROUND(F6/F7,0) -> 467 | G8: =ROUND(G6/G7,0) -> 467 | H8: =ROUND(H6/H7,0) -> 600 | I8: =ROUND(I6/I7,0) -> 600 | ... M8: =ROUND(M6/M7,0) -> 867 | N8: Paid budget / CPC
A9: Total sessions | B9: =B5+B8 -> 730 | C9: =C5+C8 -> 1020 | D9: =D5+D8 -> 1603 | E9: =E5+E8 -> 2223 | F9: =F5+F8 -> 3267 | G9: =G5+G8 -> 4417 | H9: =H5+H8 -> 5950 | I9: =I5+I8 -> 7450 | ... M9: =M5+M8 -> 13467 | N9: Non-paid subtotal + paid sessions
A10: Conversion rate | B10: 0.0085 | C10: 0.0095 | D10: 0.0105 | E10: 0.0115 | F10: 0.0125 | G10: 0.0135 | H10: 0.0145 | I10: 0.0155 | J10: 0.0165 | K10: 0.017 | L10: 0.01725 | M10: 0.0175 | N10: Ramps up as reviews, UGC, product-page education and trust improve
A11: Orders / units sold | B11: =ROUND(B9*B10,0) -> 6 | C11: =ROUND(C9*C10,0) -> 10 | D11: =ROUND(D9*D10,0) -> 17 | E11: =ROUND(E9*E10,0) -> 26 | F11: =ROUND(F9*F10,0) -> 41 | G11: =ROUND(G9*G10,0) -> 60 | H11: =ROUND(H9*H10,0) -> 86 | I11: =ROUND(I9*I10,0) -> 115 | ... M11: =ROUND(M9*M10,0) -> 236 | N11: Total sessions x conversion
A12: REVENUE & GROSS PROFIT
A13: Weighted AOV | B13: ='SKU Economics'!$H$11 -> 194.22 | C13: ='SKU Economics'!$H$11 -> 194.22 | D13: ='SKU Economics'!$H$11 -> 194.22 | E13: ='SKU Economics'!$H$11 -> 194.22 | F13: ='SKU Economics'!$H$11 -> 194.22 | G13: ='SKU Economics'!$H$11 -> 194.22 | H13: ='SKU Economics'!$H$11 -> 194.22 | I13: ='SKU Economics'!$H$11 -> 194.22 | ... M13: ='SKU Economics'!$H$11 -> 194.22 | N13: Weighted realized price
A14: Gross revenue | B14: =B11*B13 -> 1165.32 | C14: =C11*C13 -> 1942.2 | D14: =D11*D13 -> 3301.74 | E14: =E11*E13 -> 5049.72 | F14: =F11*F13 -> 7963.02 | G14: =G11*G13 -> 11653.2 | H14: =H11*H13 -> 16702.92 | I14: =I11*I13 -> 22335.3 | ... M14: =M11*M13 -> 45835.92 | N14: Orders x AOV
A15: COGS | B15: =B11*'SKU Economics'!$F$11 -> 250.8 | C15: =C11*'SKU Economics'!$F$11 -> 418 | D15: =D11*'SKU Economics'!$F$11 -> 710.6 | E15: =E11*'SKU Economics'!$F$11 -> 1086.8 | F15: =F11*'SKU Economics'!$F$11 -> 1713.8 | G15: =G11*'SKU Economics'!$F$11 -> 2508 | H15: =H11*'SKU Economics'!$F$11 -> 3594.8 | I15: =I11*'SKU Economics'!$F$11 -> 4807 | ... M15: =M11*'SKU Economics'!$F$11 -> 9864.8 | N15: Units x weighted unit cost
A16: Payment / platform fee | B16: =B14*Assumptions!$B$4 -> 34.9596 | C16: =C14*Assumptions!$B$4 -> 58.266 | D16: =D14*Assumptions!$B$4 -> 99.0522 | E16: =E14*Assumptions!$B$4 -> 151.4916 | F16: =F14*Assumptions!$B$4 -> 238.8906 | G16: =G14*Assumptions!$B$4 -> 349.596 | H16: =H14*Assumptions!$B$4 -> 501.0876 | I16: =I14*Assumptions!$B$4 -> 670.059 | ... M16: =M14*Assumptions!$B$4 -> 1375.0776 | N16: % of revenue
A17: Return / loss reserve | B17: =B14*Assumptions!$B$5 -> 34.9596 | C17: =C14*Assumptions!$B$5 -> 58.266 | D17: =D14*Assumptions!$B$5 -> 99.0522 | E17: =E14*Assumptions!$B$5 -> 151.4916 | F17: =F14*Assumptions!$B$5 -> 238.8906 | G17: =G14*Assumptions!$B$5 -> 349.596 | H17: =H14*Assumptions!$B$5 -> 501.0876 | I17: =I14*Assumptions!$B$5 -> 670.059 | ... M17: =M14*Assumptions!$B$5 -> 1375.0776 | N17: % of revenue
A18: Variable gross profit | B18: =B14-B15-B16-B17 -> 844.6008 | C18: =C14-C15-C16-C17 -> 1407.668 | D18: =D14-D15-D16-D17 -> 2393.0356 | E18: =E14-E15-E16-E17 -> 3659.9368 | F18: =F14-F15-F16-F17 -> 5771.4388 | G18: =G14-G15-G16-G17 -> 8446.008 | H18: =H14-H15-H16-H17 -> 12105.945 | I18: =I14-I15-I16-I17 -> 16188.182 | ... M18: =M14-M15-M16-M17 -> 33220.965 | N18: Rev - COGS - fee - reserve
A19: Variable gross margin | B19: =IFERROR(B18/B14,0) -> 0.72478015 | C19: =IFERROR(C18/C14,0) -> 0.72478015 | D19: =IFERROR(D18/D14,0) -> 0.72478015 | E19: =IFERROR(E18/E14,0) -> 0.72478015 | F19: =IFERROR(F18/F14,0) -> 0.72478015 | G19: =IFERROR(G18/G14,0) -> 0.72478015 | H19: =IFERROR(H18/H14,0) -> 0.72478015 | I19: =IFERROR(I18/I14,0) -> 0.72478015 | ... M19: =IFERROR(M18/M14,0) -> 0.72478015 | N19: VGP / revenue
A20: MARKETING (funds the traffic engine)
A21: Content & SEO investment | B21: 1000 | C21: 1000 | D21: 1000 | E21: 1000 | F21: 1000 | G21: 1000 | H21: 900 | I21: 900 | J21: 900 | K21: 900 | L21: 900 | M21: 900 | N21: Funds the organic ramp above; cutting this kills the organic engine
A22: Creator / UGC seeding | B22: 400 | C22: 400 | D22: 400 | E22: 400 | F22: 400 | G22: 400 | H22: 400 | I22: 400 | J22: 400 | K22: 400 | L22: 400 | M22: 400 | N22: Sample seeding, creator content
A23: Paid ads spend | B23: =B6 -> 300 | C23: =C6 -> 300 | D23: =D6 -> 500 | E23: =E6 -> 500 | F23: =F6 -> 700 | G23: =G6 -> 700 | H23: =H6 -> 900 | I23: =I6 -> 900 | ... M23: =M6 -> 1300 | N23: Equals the paid budget above
A24: Total marketing | B24: =B21+B22+B23 -> 1700 | C24: =C21+C22+C23 -> 1700 | D24: =D21+D22+D23 -> 1900 | E24: =E21+E22+E23 -> 1900 | F24: =F21+F22+F23 -> 2100 | G24: =G21+G22+G23 -> 2100 | H24: =H21+H22+H23 -> 2200 | I24: =I21+I22+I23 -> 2200 | ... M24: =M21+M22+M23 -> 2600 | N24: Content + UGC + paid
A25: OPERATING EXPENSES (excl. marketing)
A26: Labor / founder / support | B26: 0 | C26: 0 | D26: 0 | E26: 0 | F26: 0 | G26: 1400 | H26: 1600 | I26: 1800 | J26: 2000 | K26: 2200 | L26: 2400 | M26: 2600 | N26: Founder takes nothing first 5 months
A27: Fulfillment / ops overhead | B27: 120 | C27: 150 | D27: 180 | E27: 220 | F27: 260 | G27: 320 | H27: 380 | I27: 450 | J27: 520 | K27: 600 | L27: 700 | M27: 800 | N27: Storage, pick-pack, QA, supplies
A28: Software / apps | B28: 250 | C28: 250 | D28: 300 | E28: 350 | F28: 400 | G28: 450 | H28: 500 | I28: 550 | J28: 600 | K28: 650 | L28: 700 | M28: 750 | N28: Shopify, email/SMS, reviews, analytics
A29: Admin / professional | B29: 200 | C29: 200 | D29: 250 | E29: 250 | F29: 300 | G29: 300 | H29: 350 | I29: 350 | J29: 400 | K29: 400 | L29: 450 | M29: 450 | N29: Accounting, legal, bookkeeping
A30: Contingency buffer | B30: 200 | C30: 200 | D30: 250 | E30: 300 | F30: 350 | G30: 400 | H30: 450 | I30: 500 | J30: 550 | K30: 600 | L30: 650 | M30: 700 | N30: Mistakes, rush fees, replacements
A31: Total opex excl. marketing | B31: =SUM(B26:B30) -> 770 | C31: =SUM(C26:C30) -> 800 | D31: =SUM(D26:D30) -> 980 | E31: =SUM(E26:E30) -> 1120 | F31: =SUM(F26:F30) -> 1310 | G31: =SUM(G26:G30) -> 2870 | H31: =SUM(H26:H30) -> 3280 | I31: =SUM(I26:I30) -> 3650 | ... M31: =SUM(M26:M30) -> 5300 | N31: Sum of operating lines
A32: PROFIT
A33: Operating profit before tax | B33: =B18-B24-B31 -> -1625.3992 | C33: =C18-C24-C31 -> -1092.332 | D33: =D18-D24-D31 -> -486.9644 | E33: =E18-E24-E31 -> 639.9368 | F33: =F18-F24-F31 -> 2361.4388 | G33: =G18-G24-G31 -> 3476.008 | H33: =H18-H24-H31 -> 6625.9448 | I33: =I18-I24-I31 -> 10338.182 | ... M33: =M18-M24-M31 -> 25320.965 | N33: VGP - marketing - opex
A34: Operating margin | B34: =IFERROR(B33/B14,0) -> -1.3948093 | C34: =IFERROR(C33/C14,0) -> -0.56241994 | D34: =IFERROR(D33/D14,0) -> -0.1474872 | E34: =IFERROR(E33/E14,0) -> 0.12672718 | F34: =IFERROR(F33/F14,0) -> 0.29655066 | G34: =IFERROR(G33/G14,0) -> 0.29828785 | H34: =IFERROR(H33/H14,0) -> 0.3966938 | I34: =IFERROR(I33/I14,0) -> 0.46286291 | ... M34: =IFERROR(M33/M14,0) -> 0.55242624 | N34: Operating profit / revenue
A35: ACQUISITION EFFICIENCY
A36: Paid CAC ($/order) | B36: =IFERROR(B23/ROUND(B8*B10,0),0) -> 150 | C36: =IFERROR(C23/ROUND(C8*C10,0),0) -> 150 | D36: =IFERROR(D23/ROUND(D8*D10,0),0) -> 166.66667 | E36: =IFERROR(E23/ROUND(E8*E10,0),0) -> 125 | F36: =IFERROR(F23/ROUND(F8*F10,0),0) -> 116.66667 | G36: =IFERROR(G23/ROUND(G8*G10,0),0) -> 116.66667 | H36: =IFERROR(H23/ROUND(H8*H10,0),0) -> 100 | I36: =IFERROR(I23/ROUND(I8*I10,0),0) -> 100 | ... M36: =IFERROR(M23/ROUND(M8*M10,0),0) -> 86.666667 | N36: Paid spend / paid orders (now meaningful)
A37: Blended CAC ($/order) | B37: =IFERROR(B24/B11,0) -> 283.33333 | C37: =IFERROR(C24/C11,0) -> 170 | D37: =IFERROR(D24/D11,0) -> 111.76471 | E37: =IFERROR(E24/E11,0) -> 73.076923 | F37: =IFERROR(F24/F11,0) -> 51.219512 | G37: =IFERROR(G24/G11,0) -> 35 | H37: =IFERROR(H24/H11,0) -> 25.581395 | I37: =IFERROR(I24/I11,0) -> 19.130435 | ... M37: =IFERROR(M24/M11,0) -> 11.016949 | N37: Total marketing / all orders
A38: MER (revenue / marketing) | B38: =IFERROR(B14/B24,0) -> 0.68548235 | C38: =IFERROR(C14/C24,0) -> 1.1424706 | D38: =IFERROR(D14/D24,0) -> 1.7377579 | E38: =IFERROR(E14/E24,0) -> 2.6577474 | F38: =IFERROR(F14/F24,0) -> 3.7919143 | G38: =IFERROR(G14/G24,0) -> 5.5491429 | H38: =IFERROR(H14/H24,0) -> 7.5922364 | I38: =IFERROR(I14/I24,0) -> 10.152409 | ... M38: =IFERROR(M14/M24,0) -> 17.6292 | N38: Marketing efficiency ratio
A39: INVENTORY
A40: Opening inventory units | B40: =Assumptions!$B$7 -> 100 | C40: =B42 -> 94 | D40: =C42 -> 84 | E40: =D42 -> 67 | F40: =E42 -> 41 | G40: =F42 -> 41 | H40: =G42 -> 60 | I40: =H42 -> 86 | J40: =I42 -> 115 | ... M40: =L42 -> 211 | N40: M1 = initial units; else prior ending
...

Sheet Upside (Calily-match)
A1: Monthly Operating Model — Upside (Calily-match) Case
A2: Calily-match case: M12 total sessions approximate Calily's Mar-May 2026 Similarweb level; SEO is ~9.3k, not 17k.
A3: Metric | B3: M1 | C3: M2 | D3: M3 | E3: M4 | F3: M5 | G3: M6 | H3: M7 | I3: M8 | J3: M9 | K3: M10 | L3: M11 | M3: M12 | N3: Note
A4: TRAFFIC
A5: Non-paid sessions subtotal | B5: ='Channel Mix'!B32 -> 800 | C5: ='Channel Mix'!C32 -> 1270 | D5: ='Channel Mix'!D32 -> 2030 | E5: ='Channel Mix'!E32 -> 3150 | F5: ='Channel Mix'!F32 -> 4600 | G5: ='Channel Mix'!G32 -> 6350 | H5: ='Channel Mix'!H32 -> 8400 | I5: ='Channel Mix'!I32 -> 10500 | ... M5: ='Channel Mix'!M32 -> 16200 | N5: From Channel Mix: SEO + organic social + creator/affiliate + direct/referral
A6: Paid ads budget ($) | B6: ='Channel Mix'!B33 -> 300 | C6: ='Channel Mix'!C33 -> 300 | D6: ='Channel Mix'!D33 -> 500 | E6: ='Channel Mix'!E33 -> 500 | F6: ='Channel Mix'!F33 -> 700 | G6: ='Channel Mix'!G33 -> 800 | H6: ='Channel Mix'!H33 -> 900 | I6: ='Channel Mix'!I33 -> 1000 | ... M6: ='Channel Mix'!M33 -> 1600 | N6: Small paid test layer; budget lives in Channel Mix
A7: CPC ($) | B7: =Assumptions!$B$8 -> 1.5 | C7: =Assumptions!$B$8 -> 1.5 | D7: =Assumptions!$B$8 -> 1.5 | E7: =Assumptions!$B$8 -> 1.5 | F7: =Assumptions!$B$8 -> 1.5 | G7: =Assumptions!$B$8 -> 1.5 | H7: =Assumptions!$B$8 -> 1.5 | I7: =Assumptions!$B$8 -> 1.5 | ... M7: =Assumptions!$B$8 -> 1.5 | N7: From Assumptions
A8: Paid sessions | B8: =ROUND(B6/B7,0) -> 200 | C8: =ROUND(C6/C7,0) -> 200 | D8: =ROUND(D6/D7,0) -> 333 | E8: =ROUND(E6/E7,0) -> 333 | F8: =ROUND(F6/F7,0) -> 467 | G8: =ROUND(G6/G7,0) -> 533 | H8: =ROUND(H6/H7,0) -> 600 | I8: =ROUND(I6/I7,0) -> 667 | ... M8: =ROUND(M6/M7,0) -> 1067 | N8: Paid budget / CPC
A9: Total sessions | B9: =B5+B8 -> 1000 | C9: =C5+C8 -> 1470 | D9: =D5+D8 -> 2363 | E9: =E5+E8 -> 3483 | F9: =F5+F8 -> 5067 | G9: =G5+G8 -> 6883 | H9: =H5+H8 -> 9000 | I9: =I5+I8 -> 11167 | ... M9: =M5+M8 -> 17267 | N9: Non-paid subtotal + paid sessions
A10: Conversion rate | B10: 0.009 | C10: 0.01 | D10: 0.011 | E10: 0.012 | F10: 0.013 | G10: 0.014 | H10: 0.015 | I10: 0.016 | J10: 0.017 | K10: 0.0175 | L10: 0.018 | M10: 0.0185 | N10: Ramps up as reviews, UGC, product-page education and trust improve
A11: Orders / units sold | B11: =ROUND(B9*B10,0) -> 9 | C11: =ROUND(C9*C10,0) -> 15 | D11: =ROUND(D9*D10,0) -> 26 | E11: =ROUND(E9*E10,0) -> 42 | F11: =ROUND(F9*F10,0) -> 66 | G11: =ROUND(G9*G10,0) -> 96 | H11: =ROUND(H9*H10,0) -> 135 | I11: =ROUND(I9*I10,0) -> 179 | ... M11: =ROUND(M9*M10,0) -> 319 | N11: Total sessions x conversion
A12: REVENUE & GROSS PROFIT
A13: Weighted AOV | B13: ='SKU Economics'!$H$11 -> 194.22 | C13: ='SKU Economics'!$H$11 -> 194.22 | D13: ='SKU Economics'!$H$11 -> 194.22 | E13: ='SKU Economics'!$H$11 -> 194.22 | F13: ='SKU Economics'!$H$11 -> 194.22 | G13: ='SKU Economics'!$H$11 -> 194.22 | H13: ='SKU Economics'!$H$11 -> 194.22 | I13: ='SKU Economics'!$H$11 -> 194.22 | ... M13: ='SKU Economics'!$H$11 -> 194.22 | N13: Weighted realized price
A14: Gross revenue | B14: =B11*B13 -> 1747.98 | C14: =C11*C13 -> 2913.3 | D14: =D11*D13 -> 5049.72 | E14: =E11*E13 -> 8157.24 | F14: =F11*F13 -> 12818.52 | G14: =G11*G13 -> 18645.12 | H14: =H11*H13 -> 26219.7 | I14: =I11*I13 -> 34765.38 | ... M14: =M11*M13 -> 61956.18 | N14: Orders x AOV
A15: COGS | B15: =B11*'SKU Economics'!$F$11 -> 376.2 | C15: =C11*'SKU Economics'!$F$11 -> 627 | D15: =D11*'SKU Economics'!$F$11 -> 1086.8 | E15: =E11*'SKU Economics'!$F$11 -> 1755.6 | F15: =F11*'SKU Economics'!$F$11 -> 2758.8 | G15: =G11*'SKU Economics'!$F$11 -> 4012.8 | H15: =H11*'SKU Economics'!$F$11 -> 5643 | I15: =I11*'SKU Economics'!$F$11 -> 7482.2 | ... M15: =M11*'SKU Economics'!$F$11 -> 13334.2 | N15: Units x weighted unit cost
A16: Payment / platform fee | B16: =B14*Assumptions!$B$4 -> 52.4394 | C16: =C14*Assumptions!$B$4 -> 87.399 | D16: =D14*Assumptions!$B$4 -> 151.4916 | E16: =E14*Assumptions!$B$4 -> 244.7172 | F16: =F14*Assumptions!$B$4 -> 384.5556 | G16: =G14*Assumptions!$B$4 -> 559.3536 | H16: =H14*Assumptions!$B$4 -> 786.591 | I16: =I14*Assumptions!$B$4 -> 1042.9614 | ... M16: =M14*Assumptions!$B$4 -> 1858.6854 | N16: % of revenue
A17: Return / loss reserve | B17: =B14*Assumptions!$B$5 -> 52.4394 | C17: =C14*Assumptions!$B$5 -> 87.399 | D17: =D14*Assumptions!$B$5 -> 151.4916 | E17: =E14*Assumptions!$B$5 -> 244.7172 | F17: =F14*Assumptions!$B$5 -> 384.5556 | G17: =G14*Assumptions!$B$5 -> 559.3536 | H17: =H14*Assumptions!$B$5 -> 786.591 | I17: =I14*Assumptions!$B$5 -> 1042.9614 | ... M17: =M14*Assumptions!$B$5 -> 1858.6854 | N17: % of revenue
A18: Variable gross profit | B18: =B14-B15-B16-B17 -> 1266.9012 | C18: =C14-C15-C16-C17 -> 2111.502 | D18: =D14-D15-D16-D17 -> 3659.9368 | E18: =E14-E15-E16-E17 -> 5912.2056 | F18: =F14-F15-F16-F17 -> 9290.6088 | G18: =G14-G15-G16-G17 -> 13513.613 | H18: =H14-H15-H16-H17 -> 19003.518 | I18: =I14-I15-I16-I17 -> 25197.257 | ... M18: =M14-M15-M16-M17 -> 44904.609 | N18: Rev - COGS - fee - reserve
A19: Variable gross margin | B19: =IFERROR(B18/B14,0) -> 0.72478015 | C19: =IFERROR(C18/C14,0) -> 0.72478015 | D19: =IFERROR(D18/D14,0) -> 0.72478015 | E19: =IFERROR(E18/E14,0) -> 0.72478015 | F19: =IFERROR(F18/F14,0) -> 0.72478015 | G19: =IFERROR(G18/G14,0) -> 0.72478015 | H19: =IFERROR(H18/H14,0) -> 0.72478015 | I19: =IFERROR(I18/I14,0) -> 0.72478015 | ... M19: =IFERROR(M18/M14,0) -> 0.72478015 | N19: VGP / revenue
A20: MARKETING (funds the traffic engine)
A21: Content & SEO investment | B21: 1200 | C21: 1200 | D21: 1200 | E21: 1200 | F21: 1200 | G21: 1200 | H21: 1100 | I21: 1100 | J21: 1100 | K21: 1100 | L21: 1100 | M21: 1100 | N21: Funds the organic ramp above; cutting this kills the organic engine
A22: Creator / UGC seeding | B22: 600 | C22: 600 | D22: 600 | E22: 600 | F22: 600 | G22: 600 | H22: 600 | I22: 600 | J22: 600 | K22: 600 | L22: 600 | M22: 600 | N22: Sample seeding, creator content
A23: Paid ads spend | B23: =B6 -> 300 | C23: =C6 -> 300 | D23: =D6 -> 500 | E23: =E6 -> 500 | F23: =F6 -> 700 | G23: =G6 -> 800 | H23: =H6 -> 900 | I23: =I6 -> 1000 | ... M23: =M6 -> 1600 | N23: Equals the paid budget above
A24: Total marketing | B24: =B21+B22+B23 -> 2100 | C24: =C21+C22+C23 -> 2100 | D24: =D21+D22+D23 -> 2300 | E24: =E21+E22+E23 -> 2300 | F24: =F21+F22+F23 -> 2500 | G24: =G21+G22+G23 -> 2600 | H24: =H21+H22+H23 -> 2600 | I24: =I21+I22+I23 -> 2700 | ... M24: =M21+M22+M23 -> 3300 | N24: Content + UGC + paid
A25: OPERATING EXPENSES (excl. marketing)
A26: Labor / founder / support | B26: 0 | C26: 0 | D26: 0 | E26: 1500 | F26: 1800 | G26: 2000 | H26: 2200 | I26: 2400 | J26: 2600 | K26: 2800 | L26: 3000 | M26: 3200 | N26: Founder takes nothing first 5 months
A27: Fulfillment / ops overhead | B27: 150 | C27: 200 | D27: 260 | E27: 340 | F27: 440 | G27: 560 | H27: 700 | I27: 850 | J27: 1000 | K27: 1150 | L27: 1300 | M27: 1450 | N27: Storage, pick-pack, QA, supplies
A28: Software / apps | B28: 250 | C28: 300 | D28: 350 | E28: 400 | F28: 450 | G28: 500 | H28: 550 | I28: 600 | J28: 650 | K28: 700 | L28: 750 | M28: 800 | N28: Shopify, email/SMS, reviews, analytics
A29: Admin / professional | B29: 200 | C29: 250 | D29: 300 | E29: 350 | F29: 400 | G29: 450 | H29: 500 | I29: 550 | J29: 600 | K29: 650 | L29: 700 | M29: 750 | N29: Accounting, legal, bookkeeping
A30: Contingency buffer | B30: 250 | C30: 300 | D30: 350 | E30: 400 | F30: 450 | G30: 500 | H30: 550 | I30: 600 | J30: 650 | K30: 700 | L30: 750 | M30: 800 | N30: Mistakes, rush fees, replacements
A31: Total opex excl. marketing | B31: =SUM(B26:B30) -> 850 | C31: =SUM(C26:C30) -> 1050 | D31: =SUM(D26:D30) -> 1260 | E31: =SUM(E26:E30) -> 2990 | F31: =SUM(F26:F30) -> 3540 | G31: =SUM(G26:G30) -> 4010 | H31: =SUM(H26:H30) -> 4500 | I31: =SUM(I26:I30) -> 5000 | ... M31: =SUM(M26:M30) -> 7000 | N31: Sum of operating lines
A32: PROFIT
A33: Operating profit before tax | B33: =B18-B24-B31 -> -1683.0988 | C33: =C18-C24-C31 -> -1038.498 | D33: =D18-D24-D31 -> 99.9368 | E33: =E18-E24-E31 -> 622.2056 | F33: =F18-F24-F31 -> 3250.6088 | G33: =G18-G24-G31 -> 6903.6128 | H33: =H18-H24-H31 -> 11903.518 | I33: =I18-I24-I31 -> 17497.257 | ... M33: =M18-M24-M31 -> 34604.609 | N33: VGP - marketing - opex
A34: Operating margin | B34: =IFERROR(B33/B14,0) -> -0.96288218 | C34: =IFERROR(C33/C14,0) -> -0.35646792 | D34: =IFERROR(D33/D14,0) -> 0.019790563 | E34: =IFERROR(E33/E14,0) -> 0.076276486 | F34: =IFERROR(F33/F14,0) -> 0.2535869 | G34: =IFERROR(G33/G14,0) -> 0.37026379 | H34: =IFERROR(H33/H14,0) -> 0.45399139 | I34: =IFERROR(I33/I14,0) -> 0.50329544 | ... M34: =IFERROR(M33/M14,0) -> 0.55853362 | N34: Operating profit / revenue
A35: ACQUISITION EFFICIENCY
A36: Paid CAC ($/order) | B36: =IFERROR(B23/ROUND(B8*B10,0),0) -> 150 | C36: =IFERROR(C23/ROUND(C8*C10,0),0) -> 150 | D36: =IFERROR(D23/ROUND(D8*D10,0),0) -> 125 | E36: =IFERROR(E23/ROUND(E8*E10,0),0) -> 125 | F36: =IFERROR(F23/ROUND(F8*F10,0),0) -> 116.66667 | G36: =IFERROR(G23/ROUND(G8*G10,0),0) -> 114.28571 | H36: =IFERROR(H23/ROUND(H8*H10,0),0) -> 100 | I36: =IFERROR(I23/ROUND(I8*I10,0),0) -> 90.909091 | ... M36: =IFERROR(M23/ROUND(M8*M10,0),0) -> 80 | N36: Paid spend / paid orders (now meaningful)
A37: Blended CAC ($/order) | B37: =IFERROR(B24/B11,0) -> 233.33333 | C37: =IFERROR(C24/C11,0) -> 140 | D37: =IFERROR(D24/D11,0) -> 88.461538 | E37: =IFERROR(E24/E11,0) -> 54.761905 | F37: =IFERROR(F24/F11,0) -> 37.878788 | G37: =IFERROR(G24/G11,0) -> 27.083333 | H37: =IFERROR(H24/H11,0) -> 19.259259 | I37: =IFERROR(I24/I11,0) -> 15.083799 | ... M37: =IFERROR(M24/M11,0) -> 10.344828 | N37: Total marketing / all orders
A38: MER (revenue / marketing) | B38: =IFERROR(B14/B24,0) -> 0.83237143 | C38: =IFERROR(C14/C24,0) -> 1.3872857 | D38: =IFERROR(D14/D24,0) -> 2.1955304 | E38: =IFERROR(E14/E24,0) -> 3.5466261 | F38: =IFERROR(F14/F24,0) -> 5.127408 | G38: =IFERROR(G14/G24,0) -> 7.1712 | H38: =IFERROR(H14/H24,0) -> 10.0845 | I38: =IFERROR(I14/I24,0) -> 12.876067 | ... M38: =IFERROR(M14/M24,0) -> 18.7746 | N38: Marketing efficiency ratio
A39: INVENTORY
A40: Opening inventory units | B40: =Assumptions!$B$7 -> 100 | C40: =B42 -> 91 | D40: =C42 -> 76 | E40: =D42 -> 50 | F40: =E42 -> 42 | G40: =F42 -> 66 | H40: =G42 -> 96 | I40: =H42 -> 135 | J40: =I42 -> 179 | ... M40: =L42 -> 294 | N40: M1 = initial units; else prior ending
...

Sheet SKU Economics
A1: SKU Unit Economics — Confirmed Launch Matrix
A2: Blue = inputs you can edit. Black = calculated. Realized price = launch price x (1 - launch discount).
A3: SKU | B3: Production | C3: Packaging | D3: Shipping | E3: Other | F3: Fixed Cost | G3: Launch Price | H3: Realized Price | I3: Payment Fee | J3: Loss Reserve | K3: Contribution $ | L3: Contrib. Margin | M3: SKU Mix | N3: Initial Units | O3: Initial Inv. Cost
A4: Simple Cathedral Veil | B4: 10 | C4: 5 | D4: 10 | E4: 1 | F4: =SUM(B4:E4) -> 26 | G4: 129 | H4: =G4*(1-Assumptions!$B$9) -> 116.1 | I4: =H4*Assumptions!$B$4 -> 3.483 | J4: =H4*Assumptions!$B$5 -> 3.483 | K4: =H4-F4-I4-J4 -> 83.134 | L4: =K4/H4 -> 0.71605512 | M4: 0.32 | N4: 33 | O4: =F4*N4 -> 858
A5: Pearl Scatter Cathedral Veil | B5: 30 | C5: 5 | D5: 10 | E5: 1 | F5: =SUM(B5:E5) -> 46 | G5: 239 | H5: =G5*(1-Assumptions!$B$9) -> 215.1 | I5: =H5*Assumptions!$B$4 -> 6.453 | J5: =H5*Assumptions!$B$5 -> 6.453 | K5: =H5-F5-I5-J5 -> 156.194 | L5: =K5/H5 -> 0.72614598 | M5: 0.24 | N5: 22 | O5: =F5*N5 -> 1012
A6: Affordable Lace Mantilla Veil | B6: 40 | C6: 5 | D6: 10 | E6: 1 | F6: =SUM(B6:E6) -> 56 | G6: 289 | H6: =G6*(1-Assumptions!$B$9) -> 260.1 | I6: =H6*Assumptions!$B$4 -> 7.803 | J6: =H6*Assumptions!$B$5 -> 7.803 | K6: =H6-F6-I6-J6 -> 188.494 | L6: =K6/H6 -> 0.72469819 | M6: 0.16 | N6: 15 | O6: =F6*N6 -> 840
A7: Premium Lace Cathedral Veil | B7: 55 | C7: 5 | D7: 10 | E7: 1 | F7: =SUM(B7:E7) -> 71 | G7: 389 | H7: =G7*(1-Assumptions!$B$9) -> 350.1 | I7: =H7*Assumptions!$B$4 -> 10.503 | J7: =H7*Assumptions!$B$5 -> 10.503 | K7: =H7-F7-I7-J7 -> 258.094 | L7: =K7/H7 -> 0.7372008 | M7: 0.1 | N7: 12 | O7: =F7*N7 -> 852
A8: Satin Edge Mid-Length Veil | B8: 15 | C8: 5 | D8: 10 | E8: 1 | F8: =SUM(B8:E8) -> 31 | G8: 169 | H8: =G8*(1-Assumptions!$B$9) -> 152.1 | I8: =H8*Assumptions!$B$4 -> 4.563 | J8: =H8*Assumptions!$B$5 -> 4.563 | K8: =H8-F8-I8-J8 -> 111.974 | L8: =K8/H8 -> 0.73618672 | M8: 0.1 | N8: 10 | O8: =F8*N8 -> 310
A9: Pearl Puff Short Veil | B9: 25 | C9: 5 | D9: 10 | E9: 1 | F9: =SUM(B9:E9) -> 41 | G9: 189 | H9: =G9*(1-Assumptions!$B$9) -> 170.1 | I9: =H9*Assumptions!$B$4 -> 5.103 | J9: =H9*Assumptions!$B$5 -> 5.103 | K9: =H9-F9-I9-J9 -> 118.894 | L9: =K9/H9 -> 0.69896531 | M9: 0.08 | N9: 8 | O9: =F9*N9 -> 328
A11: Weighted Average / Total | F11: =SUMPRODUCT(F4:F9,M4:M9) -> 41.8 | H11: =SUMPRODUCT(H4:H9,M4:M9) -> 194.22 | L11: =SUMPRODUCT(L4:L9,M4:M9) -> 0.72262036 | M11: =SUM(M4:M9) -> 1 | N11: =SUM(N4:N9) -> 100 | O11: =SUM(O4:O9) -> 4200
A13: Key links used by the model: Weighted AOV = H11, Weighted unit cost = F11, Initial inventory cost = O11.

Sheet Assumptions
A1: Global Assumptions
A2: These constants feed all three scenarios. Blue = editable input.
A3: Starting capital before launch | B3: 8000 | C3: Recommended figure (see Startup Costs + runway buffer)
A4: Payment / platform fee | B4: 0.03 | C4: Shopify/Stripe/PayPal blended
A5: Return / damage / loss reserve | B5: 0.03 | C5: Start 3%, revisit after first 50 orders
A6: Target inventory coverage (months) | B6: 1 | C6: Restock toward ~1 month of demand
A7: Initial inventory units | B7: 100 | C7: First batch already bought pre-launch
A8: Paid traffic CPC ($) | B8: 1.5 | C8: Blended TikTok/Meta/Pinterest test cost-per-click
A9: Launch discount | B9: 0.1 | C9: Applied to launch price to get realized price
A12: Calily monthly visits benchmark | B12: 17276 | C12: Similarweb Mar-May 2026, user-provided context
A13: Calily Organic Search share | B13: 0.5384 | C13: Organic Search / total visits
A14: Calily Direct share | B14: 0.2633 | C14: Direct / total visits
A15: Calily Referral share | B15: 0.1046 | C15: Referrals / total visits
A16: Calily Organic Social share | B16: 0.0315 | C16: Organic Social / total visits
... A19: Calily Affiliate / Email share | B19: 0.0069 | C19: Each reported at ~0.69% in context

Sheet Startup Costs
A1: One-Time Startup Costs (Pre-Launch)
A2: What you spend before / at launch. The $4,200 first batch is the only inventory counted here (not double-counted in monthly).
A3: Item | B3: Cost | C3: Basis / Source
A4: First batch inventory (100 units) | B4: ='SKU Economics'!$O$11 -> 4200 | C4: Weighted SKU fixed cost x initial units
A5: Samples + pre-production iteration | B5: 500 | C5: Confirm style / color / hand-feel before bulk; 6 core + 2 editorial
A6: Product + launch content shoot | B6: 500 | C6: On-model lifestyle shots ~$50-250/image (2026 market); lean half-day
A7: Website build + veil-match quiz tool | B7: 0 | C7: Shopify theme, apps, the 'which veil fits my dress' quiz (core differentiator)
A8: Branding + first branded packaging order | B8: 0 | C8: Logo/brand assets + minimum order of boxes/tissue/inserts/hangtags
A9: Company registration + trademark | B9: 500 | C9: LLC formation + USPTO trademark filing
A10: Software annual + misc buffer | B10: 0 | C10: Upfront annual tool plans + miscellaneous
A11: Total one-time startup cost | B11: =SUM(B4:B10) -> 5700 | C11: Charged as M1 pre-launch cash in every scenario

Sheet Notes & Sources
A1: Notes & Methodology
A2: Why the assumptions look the way they do.
A4: Traffic ramp shape (the sandbox)
A5: A brand-new domain typically takes 6-12 months to rank; during the first ~3-6 months ('Google sandbox') core commercial terms like 'cathedral veil' / 'wedding veil' are suppressed and only long-tail traffic trickles in. So early organic is modeled near-zero and compounds later. Early sessions therefore come mostly from social/direct, not search. Sources: Search Engine Land, Search Engine Journal-style SEO timing guides, Ahrefs/Moz sandbox writeups (2025-2026).
A7: Why the endpoint is not crazy
A8: Calily Bridal reached ~17,276 total visits/month by Mar-May 2026 (user Similarweb PDF), with 53.84% organic search. That means the organic-search benchmark is ~9.3k/month, not 17k/month. The Base case ends below Calily's total visits; Upside matches Calily on total sessions by M12, with SEO only one channel inside the mix.
A10: Conversion rate ramp
A11: For ~$190 AOV bridal, blended ecommerce conversion sits roughly 1-2%. A brand-new site with thin trust/reviews converts at the low end and improves as reviews, content and CRO accumulate — hence a rising curve, not the old flat 1.6%.
A13: Startup costs & capital
A14: One-time setup is modeled at $5.7k in Startup Costs (inventory $4.2k + samples, lean content shoot and legal/trademark). With $8k starting capital, Base is still tight early; Conservative requires either more starting cash, lower pre-launch spend, or slower restocking.
A16: Known simplification
A17: The organic ramp is an explicit input per scenario (evidence-based shape) rather than a hard formula of cumulative content spend; it ASSUMES the content/SEO budget is actually spent each month. Paid traffic IS mechanical (budget / CPC). Revenue is collected same-month (fine for card-based DTC). Income tax, sales tax/VAT and owner draws above the labor line are excluded — operating profit is pre-tax.
A18: The channel ramp is explicit by scenario in Channel Mix. SEO is separated from organic social, creator/affiliate, and direct/referral because Calily's real path is not only TikTok and not only SEO. Paid sessions remain mechanical: budget / CPC. Revenue is collected same-month. Income tax, sales tax/VAT and owner draws above the labor line are excluded.

Sheet Channel Mix
A1: Channel Mix Calibration — Calily-Informed Growth Path
A2: Separates SEO, organic social, creator/affiliate, direct/referral and paid traffic. Scenario tabs pull their traffic rows from here.
A3: Channel | B3: M1 | C3: M2 | D3: M3 | E3: M4 | F3: M5 | G3: M6 | H3: M7 | I3: M8 | J3: M9 | K3: M10 | L3: M11 | M3: M12 | N3: Notes
A4: Conservative — SEO / organic search | B4: 20 | C4: 40 | D4: 80 | E4: 150 | F4: 300 | G4: 550 | H4: 900 | I4: 1300 | J4: 1700 | K4: 2200 | L4: 2700 | M4: 3200 | N4: Long-tail first; commercial SEO compounds after the early sandbox period.
A5: Conservative — Organic social | B5: 180 | C5: 220 | D5: 280 | E5: 350 | F5: 450 | G5: 550 | H5: 650 | I5: 750 | J5: 850 | K5: 950 | L5: 1050 | M5: 1150 | N5: TikTok / Instagram / Pinterest profile and post traffic, excluding paid clicks.
A6: Conservative — Creator + affiliate | B6: 80 | C6: 120 | D6: 170 | E6: 230 | F6: 300 | G6: 380 | H6: 470 | I6: 570 | J6: 680 | K6: 800 | L6: 930 | M6: 1050 | N6: Creator seeding, affiliate posts, bridal stylist links and review content.
A7: Conservative — Direct + referral | B7: 120 | C7: 160 | D7: 220 | E7: 300 | F7: 420 | G7: 560 | H7: 720 | I7: 900 | J7: 1100 | K7: 1300 | L7: 1500 | M7: 1700 | N7: Brand recall, saved links, email-ish dark social, referrals and repeat research sessions.
A8: Conservative — Non-paid subtotal | B8: =SUM(B4:B7) -> 400 | C8: =SUM(C4:C7) -> 540 | D8: =SUM(D4:D7) -> 750 | E8: =SUM(E4:E7) -> 1030 | F8: =SUM(F4:F7) -> 1470 | G8: =SUM(G4:G7) -> 2040 | H8: =SUM(H4:H7) -> 2740 | I8: =SUM(I4:I7) -> 3520 | ... M8: =SUM(M4:M7) -> 7100 | N8: Feeds scenario row 5.
A9: Conservative — Paid ads budget ($) | B9: 200 | C9: 200 | D9: 300 | E9: 300 | F9: 400 | G9: 400 | H9: 500 | I9: 500 | J9: 600 | K9: 600 | L9: 700 | M9: 700 | N9: Small paid testing layer; not the main growth engine.
A10: Conservative — Paid sessions | B10: =ROUND(B9/Assumptions!$B$8,0) -> 133 | C10: =ROUND(C9/Assumptions!$B$8,0) -> 133 | D10: =ROUND(D9/Assumptions!$B$8,0) -> 200 | E10: =ROUND(E9/Assumptions!$B$8,0) -> 200 | F10: =ROUND(F9/Assumptions!$B$8,0) -> 267 | G10: =ROUND(G9/Assumptions!$B$8,0) -> 267 | H10: =ROUND(H9/Assumptions!$B$8,0) -> 333 | I10: =ROUND(I9/Assumptions!$B$8,0) -> 333 | ... M10: =ROUND(M9/Assumptions!$B$8,0) -> 467 | N10: Paid budget / blended CPC.
A11: Conservative — Total sessions | B11: =B8+B10 -> 533 | C11: =C8+C10 -> 673 | D11: =D8+D10 -> 950 | E11: =E8+E10 -> 1230 | F11: =F8+F10 -> 1737 | G11: =G8+G10 -> 2307 | H11: =H8+H10 -> 3073 | I11: =I8+I10 -> 3853 | ... M11: =M8+M10 -> 7567 | N11: Non-paid subtotal + paid sessions.
A16: Base — SEO / organic search | B16: 30 | C16: 70 | D16: 150 | E16: 300 | F16: 600 | G16: 1000 | H16: 1600 | I16: 2300 | J16: 3100 | K16: 3900 | L16: 4600 | M16: 5200 | N16: Long-tail first; commercial SEO compounds after the early sandbox period.
A17: Base — Organic social | B17: 250 | C17: 350 | D17: 500 | E17: 650 | F17: 850 | G17: 1050 | H17: 1250 | I17: 1450 | J17: 1650 | K17: 1800 | L17: 1950 | M17: 2100 | N17: TikTok / Instagram / Pinterest profile and post traffic, excluding paid clicks.
A18: Base — Creator + affiliate | B18: 100 | C18: 170 | D18: 270 | E18: 420 | F18: 600 | G18: 850 | H18: 1100 | I18: 1350 | J18: 1600 | K18: 1850 | L18: 2100 | M18: 2300 | N18: Creator seeding, affiliate posts, bridal stylist links and review content.
A19: Base — Direct + referral | B19: 150 | C19: 230 | D19: 350 | E19: 520 | F19: 750 | G19: 1050 | H19: 1400 | I19: 1750 | J19: 2100 | K19: 2400 | L19: 2700 | M19: 3000 | N19: Brand recall, saved links, email-ish dark social, referrals and repeat research sessions.
A20: Base — Non-paid subtotal | B20: =SUM(B16:B19) -> 530 | C20: =SUM(C16:C19) -> 820 | D20: =SUM(D16:D19) -> 1270 | E20: =SUM(E16:E19) -> 1890 | F20: =SUM(F16:F19) -> 2800 | G20: =SUM(G16:G19) -> 3950 | H20: =SUM(H16:H19) -> 5350 | I20: =SUM(I16:I19) -> 6850 | ... M20: =SUM(M16:M19) -> 12600 | N20: Feeds scenario row 5.
A21: Base — Paid ads budget ($) | B21: 300 | C21: 300 | D21: 500 | E21: 500 | F21: 700 | G21: 700 | H21: 900 | I21: 900 | J21: 1100 | K21: 1100 | L21: 1300 | M21: 1300 | N21: Small paid testing layer; not the main growth engine.
A22: Base — Paid sessions | B22: =ROUND(B21/Assumptions!$B$8,0) -> 200 | C22: =ROUND(C21/Assumptions!$B$8,0) -> 200 | D22: =ROUND(D21/Assumptions!$B$8,0) -> 333 | E22: =ROUND(E21/Assumptions!$B$8,0) -> 333 | F22: =ROUND(F21/Assumptions!$B$8,0) -> 467 | G22: =ROUND(G21/Assumptions!$B$8,0) -> 467 | H22: =ROUND(H21/Assumptions!$B$8,0) -> 600 | I22: =ROUND(I21/Assumptions!$B$8,0) -> 600 | ... M22: =ROUND(M21/Assumptions!$B$8,0) -> 867 | N22: Paid budget / blended CPC.
A23: Base — Total sessions | B23: =B20+B22 -> 730 | C23: =C20+C22 -> 1020 | D23: =D20+D22 -> 1603 | E23: =E20+E22 -> 2223 | F23: =F20+F22 -> 3267 | G23: =G20+G22 -> 4417 | H23: =H20+H22 -> 5950 | I23: =I20+I22 -> 7450 | ... M23: =M20+M22 -> 13467 | N23: Non-paid subtotal + paid sessions.
A28: Upside (Calily-match) — SEO / organic search | B28: 50 | C28: 120 | D28: 280 | E28: 600 | F28: 1200 | G28: 2100 | H28: 3400 | I28: 4800 | J28: 6200 | K28: 7600 | L28: 8700 | M28: 9300 | N28: Long-tail first; commercial SEO compounds after the early sandbox period.
A29: Upside (Calily-match) — Organic social | B29: 350 | C29: 500 | D29: 700 | E29: 900 | F29: 1100 | G29: 1250 | H29: 1350 | I29: 1450 | J29: 1500 | K29: 1500 | L29: 1500 | M29: 1500 | N29: TikTok / Instagram / Pinterest profile and post traffic, excluding paid clicks.
A30: Upside (Calily-match) — Creator + affiliate | B30: 180 | C30: 300 | D30: 500 | E30: 800 | F30: 1100 | G30: 1400 | H30: 1650 | I30: 1850 | J30: 2000 | K30: 2100 | L30: 2150 | M30: 2200 | N30: Creator seeding, affiliate posts, bridal stylist links and review content.
A31: Upside (Calily-match) — Direct + referral | B31: 220 | C31: 350 | D31: 550 | E31: 850 | F31: 1200 | G31: 1600 | H31: 2000 | I31: 2400 | J31: 2800 | K31: 3000 | L31: 3100 | M31: 3200 | N31: Brand recall, saved links, email-ish dark social, referrals and repeat research sessions.
A32: Upside (Calily-match) — Non-paid subtotal | B32: =SUM(B28:B31) -> 800 | C32: =SUM(C28:C31) -> 1270 | D32: =SUM(D28:D31) -> 2030 | E32: =SUM(E28:E31) -> 3150 | F32: =SUM(F28:F31) -> 4600 | G32: =SUM(G28:G31) -> 6350 | H32: =SUM(H28:H31) -> 8400 | I32: =SUM(I28:I31) -> 10500 | ... M32: =SUM(M28:M31) -> 16200 | N32: Feeds scenario row 5.
A33: Upside (Calily-match) — Paid ads budget ($) | B33: 300 | C33: 300 | D33: 500 | E33: 500 | F33: 700 | G33: 800 | H33: 900 | I33: 1000 | J33: 1100 | K33: 1200 | L33: 1300 | M33: 1600 | N33: Small paid testing layer; not the main growth engine.
A34: Upside (Calily-match) — Paid sessions | B34: =ROUND(B33/Assumptions!$B$8,0) -> 200 | C34: =ROUND(C33/Assumptions!$B$8,0) -> 200 | D34: =ROUND(D33/Assumptions!$B$8,0) -> 333 | E34: =ROUND(E33/Assumptions!$B$8,0) -> 333 | F34: =ROUND(F33/Assumptions!$B$8,0) -> 467 | G34: =ROUND(G33/Assumptions!$B$8,0) -> 533 | H34: =ROUND(H33/Assumptions!$B$8,0) -> 600 | I34: =ROUND(I33/Assumptions!$B$8,0) -> 667 | ... M34: =ROUND(M33/Assumptions!$B$8,0) -> 1067 | N34: Paid budget / blended CPC.
A35: Upside (Calily-match) — Total sessions | B35: =B32+B34 -> 1000 | C35: =C32+C34 -> 1470 | D35: =D32+D34 -> 2363 | E35: =E32+E34 -> 3483 | F35: =F32+F34 -> 5067 | G35: =G32+G34 -> 6883 | H35: =H32+H34 -> 9000 | I35: =I32+I34 -> 11167 | ... M35: =M32+M34 -> 17267 | N35: Non-paid subtotal + paid sessions.
A40: Calily Benchmark (Similarweb Mar-May 2026) | B40: Value | C40: Share | D40: Monthly sessions | E40: Use in model
A41: Total visits / month | B41: 17276 | C41: 1 | D41: 17276 | E41: Upside M12 total sessions target, not SEO-only target
A42: Organic Search | C42: 0.5384 | D42: =B41*C42 -> 9301.3984 | E42: Calily SEO benchmark is ~9.3k/month
A43: Direct | C43: 0.2633 | D43: =B41*C43 -> 4548.7708 | E43: Brand recall / repeat research / dark social
A44: Referrals | C44: 0.1046 | D44: =B41*C44 -> 1807.0696 | E44: Partner, affiliate and referral-like traffic
A45: Organic Social | C45: 0.0315 | D45: =B41*C45 -> 544.194 | E45: Reported website-attributed social is small
A46: Paid Social | C46: 0.0188 | D46: =B41*C46 -> 324.7888 | E46: Small paid layer
A47: Paid Search | C47: 0.0055 | D47: =B41*C47 -> 95.018 | E47: Very small paid search layer
A48: Affiliate / Email each | C48: 0.0069 | D48: =B41*C48 -> 119.2044 | E48: Small identified share; may be under-attributed
A49: Source | B49: User Similarweb PDF summarized in context MD | C49: Mar-May 2026 | E49: Calily had 53.84% organic search and 26.33% direct, so the real path is SEO + brand/direct + referral, not only social.
